Workbook

Sheet Sheet1 (2)
B2: client status | C2: Mapped code | D2: Client | E2: Mar Final chargeable weight | F2: Mar Total Revenue | G2: Feb RPK | H2: Apr Final chargeable weight | I2: Apr Total Revenue | J2: Apr RPK | K2: Rev diff | L2: Comemnt | M2: remarks | N2: Rev % | O2: others | P2: KAM
B3: New client (Aug'25) | C3: Himalaya_Wellness_B2B | D3: HIMALAYA WELLNESS COMPANY | E3: 0 | F3: 364 | G3: 0 | H3: 405578 | I3: 2691253 | J3: 6.6355991 | K3: 2690889 | L3: Top 20 | N3: 7392.5522 | P3: Nadir
B4: New client (Feb'26) | C4: PROELIUM_B2B | D4: Proelium Learning Solutions Private Limited | E4: 5663 | F4: 53219 | G4: 9.3976691 | H4: 28045 | I4: 961501 | J4: 34.284222 | K4: 908282 | L4: Top 20 | N4: 17.066875 | P4: Sanchit
B5: 0 | C5: ASIAN_RETAIL_B2B | D5: ASIAN RETAIL VENTURES | E5: 0 | F5: 0 | G5: 0 | H5: 79542 | I5: 864401 | J5: 10.867227 | K5: 864401 | L5: Top 20 | N5: #DIV/0! | P5: Rahul
B6: New (Aug) | C6: AbrosSports_B2B | D6: ABROS SPORTS INTERNATIONAL PRIVATE LIMITED | E6: 160436 | F6: 1497477 | G6: 9.3337967 | H6: 132434 | I6: 2361616 | J6: 17.8324 | K6: 864139 | L6: Top 20 | N6: 0.57706329 | P6: Keshav
B7: New client (Nov'25) | C7: MVIKAS_B2B | D7: MVIKAS SUPER LOGISTICS PRIVATE LIMITED | E7: 48367 | F7: 554088 | G7: 11.45591 | H7: 102702 | I7: 1279882 | J7: 12.462094 | K7: 725794 | L7: Top 20 | N7: 1.3098894 | P7: Gaurav
B8: New July'24 | C8: Signify_Innovations_B2B | D8: SIGNIFY INNOVATIONS INDIA LIMITED | E8: 123482 | F8: 961020 | G8: 7.7826728 | H8: 231417 | I8: 1677383 | J8: 7.2483137 | K8: 716363 | L8: Top 20 | N8: 0.74541945 | P8: Amrit
B9: 0 | C9: GodrejBoyce_B2B | D9: GODREJ AND BOYCE MANUFACTURING CO LTD. | E9: 46256 | F9: 594199 | G9: 12.845879 | H9: 114592 | I9: 1299454 | J9: 11.339832 | K9: 705255 | L9: Top 20 | N9: 1.1869003 | P9: Keshav
B10: 0 | C10: Apollosupplychain_B2B | D10: Apollo Supply Chain Private Limited | E10: 70627 | F10: 959537 | G10: 13.58598 | H10: 121242 | I10: 1552474 | J10: 12.804754 | K10: 592937 | L10: Top 20 | N10: 0.61794074 | P10: Tasleem
B11: New client (Feb'26) | C11: KORES_OUTBOUND_B2B | D11: KORES INDIA LIMITED | E11: 50971 | F11: 403873 | G11: 7.923584 | H11: 128449 | I11: 995455 | J11: 7.7498073 | K11: 591582 | L11: Top 20 | N11: 1.4647723 | P11: Pratik
B12: New Client(March'26) | C12: RASNA_INDIA_B2B | D12: RASNA PRIVATE LIMITED | E12: 0 | F12: 0 | G12: 0 | H12: 73865 | I12: 565439 | J12: 7.6550328 | K12: 565439 | L12: Top 20 | N12: #DIV/0! | P12: Pooja
B13: New client (Feb'26) | C13: CARGOWALE_B2B | D13: B2B CARGOWALE PRIVATE LIMITED | E13: 9892 | F13: 101958 | G13: 10.307117 | H13: 65989 | I13: 638681 | J13: 9.6785979 | K13: 536723 | L13: Top 20 | N13: 5.2641578 | P13: Avinash
B14: New client (Aug'25) | C14: CULTSPORT_Haryana_B2B | D14: CULTSPORT PRIVATE LIMITED | E14: 1314 | F14: 26752 | G14: 20.359209 | H14: 37401 | I14: 496260 | J14: 13.268629 | K14: 469508 | L14: Top 20 | N14: 17.550389 | P14: Harisha
B15: 0 | C15: PD_Logistics_B2B | D15: PD LOGISTICS | E15: 1915 | F15: 19059 | G15: 9.9524804 | H15: 39571 | I15: 484698 | J15: 12.248819 | K15: 465639 | L15: Top 20 | N15: 24.43145 | P15: Sanchit
B16: 0 | C16: Sassafras_B2B | D16: Kalyr Retail Private Limited | E16: 23224 | F16: 333149 | G16: 14.345031 | H16: 56908 | I16: 782216 | J16: 13.745273 | K16: 449067 | L16: Top 20 | N16: 1.3479464 | P16: Tasleem
B17: New(Jan) | C17: ACEFOUR_ACCESSORIES_B2B | D17: ACEFOUR ACCESSORIES PRIVATE LIMITED | E17: 26052 | F17: 203353 | G17: 7.8056579 | H17: 77454 | I17: 643726 | J17: 8.311075 | K17: 440373 | L17: Top 20 | N17: 2.1655594 | P17: Pratik
B18: New Client(April'26) | C18: PROZO_INTEGRATED_B2B | D18: PROZO INTEGRATED LOGISTICS PRIVATE LIMITED | E18: 0 | F18: 0 | G18: 0 | H18: 43756 | I18: 424667 | J18: 9.7053433 | K18: 424667 | L18: Top 20 | N18: #DIV/0! | P18: Avinash
B19: New client (Feb'26) | C19: ALPINO_B2B | D19: ALPINO HEALTH FOODS PRIVATE LIMITED | E19: 3000 | F19: 44332 | G19: 14.777333 | H19: 30944 | I19: 422423 | J19: 13.651209 | K19: 378091 | L19: Top 20 | N19: 8.5286249 | P19: Pooja
B20: New Client(March'26) | C20: HACHI_B2B | D20: HACHI WILSON INDIA | E20: 1978 | F20: 24271 | G20: 12.270475 | H20: 27867 | I20: 385470 | J20: 13.83249 | K20: 361199 | L20: Top 20 | N20: 14.881917 | P20: Avinash
B21: New client (Oct'25) | C21: TUAREG_B2B | D21: TUAREG MARKETING PRIVATE LIMITED | E21: 3448 | F21: 41317 | G21: 11.982889 | H21: 36967 | I21: 369688 | J21: 10.000487 | K21: 328371 | L21: Top 20 | N21: 7.9476003 | P21: Deepika
B22: New client (Mar'26) | C22: PANCHANAN_B2B | D22: PANCHANAN INTERNATIONAL PRIVATE LIMITED | E22: 10697 | F22: 110130 | G22: 10.29541 | H22: 33676 | I22: 399467 | J22: 11.862068 | K22: 289337 | L22: Top 20 | N22: 2.6272315 | P22: Rahul
B23: 0 | C23: AGILITAS_B2B | D23: AGILITAS BRANDS PRIVATE LIMITED | E23: 41251 | F23: 606672 | G23: 14.706843 | H23: 56401 | I23: 894337 | J23: 15.856758 | K23: 287665 | N23: 0.47416891 | P23: Harisha
B24: new may'25 | C24: LITTLE_B2B | D24: LITTLE RUNWAYS WHOLESALE PRIVATE LIMITED | E24: 67477 | F24: 648628 | G24: 9.6125791 | H24: 98957 | I24: 933987 | J24: 9.4383116 | K24: 285359 | N24: 0.43994246 | P24: Pratik
B25: 0 | C25: Bolasagro_B2B | D25: BOLAS AGRO PRIVATE LIMITED | E25: 7857 | F25: 164181 | G25: 20.896144 | H25: 33454 | I25: 446695 | J25: 13.352514 | K25: 282514 | N25: 1.7207472 | P25: Keshav
B26: New client (Oct'25) | C26: KARCHER_B2B | D26: KARCHER CLEANING SYSTEMS PRIVATE LIMITED | E26: 21083 | F26: 332874 | G26: 15.78874 | H26: 41051 | I26: 606716 | J26: 14.779567 | K26: 273842 | N26: 0.82265962 | P26: Kaushal
B27: New client (July'25) | C27: HD_Enterprise_B2B | D27: HD ENTERPRISE | E27: 9664 | F27: 119081 | G27: 12.322123 | H27: 32100 | I27: 389391 | J27: 12.130561 | K27: 270310 | N27: 2.2699675 | P27: Kaushal
B28: New client (Mar'26) | C28: Prateek_B2B | D28: PRATEEK ENTERPRISES | E28: 25569 | F28: 214364 | G28: 8.3837459 | H28: 44482 | I28: 482669 | J28: 10.850884 | K28: 268305 | N28: 1.2516327 | P28: Sanchit
B29: New client (Oct'25) | C29: STYLE_WAVES_B2B | D29: STYLE WAVES LLP | E29: 1664 | F29: 43923 | G29: 26.396034 | H29: 16085 | I29: 297400 | J29: 18.489276 | K29: 253477 | N29: 5.7709401 | P29: Avinash
B30: new client(march'25) | C30: Dollar_B2B | D30: Dollar Industries Limited | E30: 105487 | F30: 1092547 | G30: 10.357172 | H30: 122915 | I30: 1324192 | J30: 10.773234 | K30: 231645 | N30: 0.21202292 | P30: Keshav
B31: New client (Mar'26) | C31: JAMBULOGIX_B2B | D31: JAMBULOGIX PRIVATE LIMITED | E31: 14362 | F31: 146438 | G31: 10.196212 | H31: 32862 | I31: 376499 | J31: 11.456972 | K31: 230061 | N31: 1.5710471 | P31: Aman
B32: New (Aug) | C32: ATMOS_CARE_B2B | D32: ATMOS CARE PRIVATE LIMITED | E32: 24351 | F32: 320136 | G32: 13.146729 | H32: 38069 | I32: 547747 | J32: 14.388269 | K32: 227611 | N32: 0.71098221 | P32: Harisha
B33: New client (Apr'26) | C33: CJ_DARCL_CERAGEM_B2B | D33: CJ DARCL LOGISTICS LIMITED | E33: 0 | F33: 0 | G33: 0 | H33: 27053 | I33: 224599 | J33: 8.3021846 | K33: 224599 | L33: New client | N33: #DIV/0! | P33: Rahul
B34: New client (june'25) | C34: MIDVISION_B2B | D34: MIDVISION PRIVATE LIMITED | E34: 35 | F34: 1223 | G34: 34.942857 | H34: 2784 | I34: 218988 | J34: 78.659483 | K34: 217765 | N34: 178.05805 | P34: aman
B35: New(Jan) | C35: YASH_SEALS_B2B | D35: YASH SEALS PRIVATE LIMITED | E35: 66009 | F35: 804585 | G35: 12.18902 | H35: 94180 | I35: 1021432 | J35: 10.84553 | K35: 216847 | N35: 0.2695141 | P35: Pratik
B36: New client (june'25) | C36: PUREPLAY_B2B | D36: PUREPLAY SKIN SCIENCES (INDIA) PRIVATE LIMITED | E36: 46027 | F36: 416853 | G36: 9.0567058 | H36: 59006 | I36: 633543 | J36: 10.736925 | K36: 216690 | N36: 0.51982353 | P36: Nadir
B37: 0 | C37: Arvind_B2B | D37: Arvind Fashions Limited | E37: 683 | F37: 8214 | G37: 12.026354 | H37: 18694 | I37: 219914 | J37: 11.763881 | K37: 211700 | N37: 25.77307 | P37: Harshith S
B38: New Client(April'26) | C38: XEOM_B2B | D38: XEOM CONSUMER PRIVATE LIMITED | E38: 0 | F38: 0 | G38: 0 | H38: 22362 | I38: 211457 | J38: 9.4560862 | K38: 211457 | L38: New client | N38: #DIV/0! | P38: Avinash
B39: 0 | C39: Arvind_B2B | D39: Arvind Youth Brands Private Limited | E39: 0 | F39: 0 | G39: 0 | H39: 17760 | I39: 209234 | J39: 11.781194 | K39: 209234 | L39: Revival | N39: #DIV/0! | P39: Harshith S
B40: New Client(March'26) | C40: LOGYXPRESS_B2B | D40: LOGYXPRESS | E40: 6932 | F40: 78626 | G40: 11.34247 | H40: 21264 | I40: 279608 | J40: 13.14936 | K40: 200982 | N40: 2.5561773 | P40: Aman
B41: New client (April26) | C41: MICROPARK_B2B | D41: MICROPARK LOGISTICS PRIVATE LIMITED | E41: 0 | F41: 0 | G41: 0 | H41: 41458 | I41: 195956 | J41: 4.7266149 | K41: 195956 | L41: New client | N41: #DIV/0! | P41: Chandresh
...

Sheet Making process
B2: steps | C2: get data | G2: descp
B3: 1 | C3: churn client | D3: make filter on mar rev is >0 and apr rev is <0 | F3: 1 | G3: get the data from the ramya or Shikha | H3: -
B4: 2 | C4: top 20 | D4: take top 20 rev numbers in mar-apr diff column | F4: 2 | G4: map all the data | H4: -
B5: 3 | C5: bottom 20 | D5: take bottom 20 rev numbers in mar-apr diff column | F5: - | G5: Map the latest kam for all the clients | H5: -
B6: 4 | C6: near churn | D6: make a number filter in the Rev% column and apply the logic [-0.7]. | E6: Churn client | F6: 3 | G6: Make the filter in M-2 Revenue (>0) AND M-1 revenue (<0). | H6: then u can indentify the Which clients as not given the rev in M2 month for thease type of client mark as Churn clients
E7: Top 20 | F7: 4 | G7: remove the current month onboarding client and filter the top 20 clients, and mark that as top 20 in comment column | H7: top 20 higher revenue, compared to last month revenue
E8: Bottom 20 | F8: 5 | G8: fiter the bottom 20 in the REVENUE DIFF column.and don’t remove the churn client comment in the comment column | H8: bottom 20 higher revenue, compared to last month revenue.
E9: near churn | F9: 6 | G9: filter the -70% in Rev% diff , and then and unfilter the comment that we are already written in the comment column

Sheet view
C2: B2B Jul | D2: B2B Aug
B3: Total number of client | C3: 348 | D3: =COUNTIF(Base!I3:I437, "<>0") -> 387
B4: Number of client uptrending | C4: 227 | D4: =COUNTIF(Base!K4:K437, ">0") -> 223
B5: Number of client downtrending | C5: 163 | D5: =COUNTIF(Base!K5:K437, "<0") -> 211
B6: Growth/De Growth | C6: 1.392638 | D6: =D4/D5 -> 1.056872
B7: Churn Count | C7: 43 | D7: =COUNTIF(Base!$M:$M,"Churn client") -> 48
B8: Near Lost(>70% Rev loss) | C8: 27 | D8: =COUNTIF(Base!$M:$M,"Near Churn") -> 35
C10: =SUM(C12:C59) -> 5919958.3
B11: Churn clients | C11: Jul rev | D11: Promised Rev | E11: KAM/BD | F11: Remarks
B12: {=_xlfn._xlws.FILTER(Base!D:D,Base!M:M="Churn client", "No clients found")} -> XCELL SUPPLY CHAIN SOLUTIONS PRIVATE LIMITED | C12: =SUMIFS(Base!F:F,Base!D:D,view!B12) -> 450 | E12: =_xlfn.XLOOKUP($B12,Base!D:D,Base!R:R) -> Deepak Jha
B13: SHREE MARUTI INTEGRATED LOGISTICS LIMITED | C13: =SUMIFS(Base!F:F,Base!D:D,view!B13) -> 515.8 | E13: =_xlfn.XLOOKUP($B13,Base!D:D,Base!R:R) -> Pratik
B14: SHIP AGGREGATOR TECHNOLOGY PRIVATE LIMITED | C14: =SUMIFS(Base!F:F,Base!D:D,view!B14) -> 1234 | E14: =_xlfn.XLOOKUP($B14,Base!D:D,Base!R:R) -> Suraj
B15: INNISFREE COSMETICS INDIA PVT LTD | C15: =SUMIFS(Base!F:F,Base!D:D,view!B15) -> 1279.496 | E15: =_xlfn.XLOOKUP($B15,Base!D:D,Base!R:R) -> Aman
B16: ShaTab Consulting and Distribution Private Limited | C16: =SUMIFS(Base!F:F,Base!D:D,view!B16) -> 1296.5 | E16: =_xlfn.XLOOKUP($B16,Base!D:D,Base!R:R) -> Avinash
B17: MICROTEK INTERNATIONAL PRIVATE LIMITED | C17: =SUMIFS(Base!F:F,Base!D:D,view!B17) -> 2453 | E17: =_xlfn.XLOOKUP($B17,Base!D:D,Base!R:R) -> Rahul
B18: UARPAL Metalcraft | C18: =SUMIFS(Base!F:F,Base!D:D,view!B18) -> 2519.76 | E18: =_xlfn.XLOOKUP($B18,Base!D:D,Base!R:R) -> Deepak Jha
B19: AMAR BIO ORGANICS INDIA PVT LTD | C19: =SUMIFS(Base!F:F,Base!D:D,view!B19) -> 3589 | E19: =_xlfn.XLOOKUP($B19,Base!D:D,Base!R:R) -> Sahilesh
B20: CHIRANTANA EQUIPACK PRIVATE LIMITED | C20: =SUMIFS(Base!F:F,Base!D:D,view!B20) -> 4540.75 | E20: =_xlfn.XLOOKUP($B20,Base!D:D,Base!R:R) -> Subhash
B21: NIMESH ENTERPRISES | C21: =SUMIFS(Base!F:F,Base!D:D,view!B21) -> 4858.2 | E21: =_xlfn.XLOOKUP($B21,Base!D:D,Base!R:R) -> Shekhar
B22: FABIANO APPLIANCES PRIVATE LIMITED | C22: =SUMIFS(Base!F:F,Base!D:D,view!B22) -> 5255.85 | E22: =_xlfn.XLOOKUP($B22,Base!D:D,Base!R:R) -> Deepak Jha
B23: LOTUS BLISS | C23: =SUMIFS(Base!F:F,Base!D:D,view!B23) -> 5343.7 | E23: =_xlfn.XLOOKUP($B23,Base!D:D,Base!R:R) -> Pooja
B24: MAHAVIR TRANSPORT SERVICE | C24: =SUMIFS(Base!F:F,Base!D:D,view!B24) -> 5614 | E24: =_xlfn.XLOOKUP($B24,Base!D:D,Base!R:R) -> Raj Kamal
... B59: Yolojet Internet Services Private Limited | C59: =SUMIFS(Base!F:F,Base!D:D,view!B59) -> 2982224 | E59: =_xlfn.XLOOKUP($B59,Base!D:D,Base!R:R) -> Harisha
C61: =SUM(C63:C97) -> 5540510.3 | D61: =SUM(D63:D97) -> 834813
B62: Near Lost | C62: Jul Net Rev | D62: Aug Net Rev | E62: Promised Rev | F62: KAM/BD | G62: Remarks
B63: {=_xlfn._xlws.FILTER(Base!D:D,Base!M:M="Near churn", "No clients found")} -> ASMR BITES PRIVATE LIMITED | C63: =SUMIFS(Base!F:F,Base!D:D,view!B63) -> 3781.55 | D63: =SUMIFS(Base!I:I,Base!D:D,view!B63) -> 834 | F63: =_xlfn.XLOOKUP($B63,Base!D:D,Base!R:R) -> Ashray
B64: TEKIES RETAIL PRIVATE LIMITED | C64: =SUMIFS(Base!F:F,Base!D:D,view!B64) -> 3672 | D64: =SUMIFS(Base!I:I,Base!D:D,view!B64) -> 482 | F64: =_xlfn.XLOOKUP($B64,Base!D:D,Base!R:R) -> Deepak Jha
B65: EXYTE SOLUTIONS PRIVATE LIMITED | C65: =SUMIFS(Base!F:F,Base!D:D,view!B65) -> 5317.86 | D65: =SUMIFS(Base!I:I,Base!D:D,view!B65) -> 405 | F65: =_xlfn.XLOOKUP($B65,Base!D:D,Base!R:R) -> Deepak Jha
B66: Shiplystic Pvt Ltd | C66: =SUMIFS(Base!F:F,Base!D:D,view!B66) -> 8674.895 | D66: =SUMIFS(Base!I:I,Base!D:D,view!B66) -> 2497 | F66: =_xlfn.XLOOKUP($B66,Base!D:D,Base!R:R) -> Pratik
B67: BOGGLETREE TECHNOLOGIES PRIVATE LIMITED | C67: =SUMIFS(Base!F:F,Base!D:D,view!B67) -> 16718.32 | D67: =SUMIFS(Base!I:I,Base!D:D,view!B67) -> 2615 | F67: =_xlfn.XLOOKUP($B67,Base!D:D,Base!R:R) -> Rahul
B68: SMILEPHILE HEALTHCARE PRIVATE LIMITED | C68: =SUMIFS(Base!F:F,Base!D:D,view!B68) -> 17465 | D68: =SUMIFS(Base!I:I,Base!D:D,view!B68) -> 1460 | F68: =_xlfn.XLOOKUP($B68,Base!D:D,Base!R:R) -> Saud
B69: MICROPARK LOGISTICS PRIVATE LIMITED | C69: =SUMIFS(Base!F:F,Base!D:D,view!B69) -> 20103.5 | D69: =SUMIFS(Base!I:I,Base!D:D,view!B69) -> 3344 | F69: =_xlfn.XLOOKUP($B69,Base!D:D,Base!R:R) -> Deepak Jha
B70: LOGYXPRESS | C70: =SUMIFS(Base!F:F,Base!D:D,view!B70) -> 18665 | D70: =SUMIFS(Base!I:I,Base!D:D,view!B70) -> 1861 | F70: =_xlfn.XLOOKUP($B70,Base!D:D,Base!R:R) -> Deepak Jha
B71: BETTERLIFE HORIZONS PRIVATE LIMITED | C71: =SUMIFS(Base!F:F,Base!D:D,view!B71) -> 19258.16 | D71: =SUMIFS(Base!I:I,Base!D:D,view!B71) -> 1660 | F71: =_xlfn.XLOOKUP($B71,Base!D:D,Base!R:R) -> Avinash
B72: GRAND SPEED NETWORK PRIVATE LIMITED | C72: =SUMIFS(Base!F:F,Base!D:D,view!B72) -> 37791.72 | D72: =SUMIFS(Base!I:I,Base!D:D,view!B72) -> 7845 | F72: =_xlfn.XLOOKUP($B72,Base!D:D,Base!R:R) -> Pratik
B73: SEOUL IMPEX | C73: =SUMIFS(Base!F:F,Base!D:D,view!B73) -> 35131.3 | D73: =SUMIFS(Base!I:I,Base!D:D,view!B73) -> 3669 | F73: =_xlfn.XLOOKUP($B73,Base!D:D,Base!R:R) -> Subhash
B74: TENSOR LOGISTICS PRIVATE LIMITED | C74: =SUMIFS(Base!F:F,Base!D:D,view!B74) -> 43044.67 | D74: =SUMIFS(Base!I:I,Base!D:D,view!B74) -> 11335 | F74: =_xlfn.XLOOKUP($B74,Base!D:D,Base!R:R) -> Deepak Jha
B75: Lighthouse Learning Private Limited | C75: =SUMIFS(Base!F:F,Base!D:D,view!B75) -> 35941.42 | D75: =SUMIFS(Base!I:I,Base!D:D,view!B75) -> 3076 | F75: =_xlfn.XLOOKUP($B75,Base!D:D,Base!R:R) -> Kunal
... B97: TATA 1MG HEALTHCARE SOLUTIONS PRIVATE LIMITED | C97: =SUMIFS(Base!F:F,Base!D:D,view!B97) -> 463274.6 | D97: =SUMIFS(Base!I:I,Base!D:D,view!B97) -> 4806 | F97: =_xlfn.XLOOKUP($B97,Base!D:D,Base!R:R) -> Gaurav
B99: Bottom 20 clients | F99: =SUM(F101:F120) -> -21307509
...

Sheet Base
E1: =SUBTOTAL(9,E3:E464) -> 11717374 | F1: =SUBTOTAL(9,F3:F464) -> 1.5605827e+08 | G1: =F1/E1 -> 13.318536 | H1: =SUBTOTAL(9,H3:H464) -> 13384624 | I1: =SUBTOTAL(9,I3:I464) -> 166966615 | J1: =I1/H1 -> 12.47451 | T1: Mar vs Apr
B2: client status | C2: Mapped code | D2: Client | E2: Jul Final chargeable weight (kg) | F2: Jul Total Revenue | G2: Jul RPK | H2: Aug Final chargeable weight (kg) | I2: Aug Total Revenue | J2: Aug RPK | K2: Rev diff | L2: TON Diff | M2: Comemnt | N2: remarks | O2: Rev % | P2: TON % | Q2: others | R2: KAM | T2: Mar Final chargeable weight | U2: Mar Total Revenue | V2: Mar RPK | W2: Rev diff | X2: Rev % | Y2: Comemnt
A3: 1MG_B2B | B3: New client (Aug'26) | C3: HYUNDAI_GLOVIS_B2B | D3: GLOVIS INDIA PRIVATE LIMITED | E3: 0 | F3: 0 | G3: =IFERROR((F3/E3),0) -> 0 | H3: 820961 | I3: 8361860 | J3: =IFERROR((I3/H3),0) -> 10.185453 | K3: =I3-F3 -> 8361860 | L3: =(H3-E3)/1000 -> 820.961 | M3: - | O3: =K3/F3 -> #DIV/0! | P3: =L3/(E3/1000) -> #DIV/0! | R3: Padma | T3: 0 | U3: 0 | V3: =IFERROR((U3/T3),0) -> 0 | W3: =F3-U3 -> 0 | X3: =W3/F3 -> #DIV/0!
A4: 4TH_PHARMA_B2B | B4: - | C4: Raymond_Home_Ltd_B2B | D4: RAYMOND LIFESTYLE LIMITED | E4: 343560 | F4: 8418640 | G4: =IFERROR((F4/E4),0) -> 24.504133 | H4: 361749 | I4: 12830806 | J4: =IFERROR((I4/H4),0) -> 35.468808 | K4: =I4-F4 -> 4412166 | L4: =(H4-E4)/1000 -> 18.189 | M4: Top 20 | O4: =K4/F4 -> 0.52409487 | P4: =L4/(E4/1000) -> 0.052942717 | R4: Aditi | T4: 0 | U4: 0 | V4: =IFERROR((U4/T4),0) -> 0 | W4: =F4-U4 -> 8418640 | X4: =W4/F4 -> 1
A5: 6HEIGHT_B2B | B5: - | C5: Campus_B2B | D5: CAMPUS ACTIVEWEAR LIMITED | E5: 232941 | F5: 2143724 | G5: =IFERROR((F5/E5),0) -> 9.2028625 | H5: 571090 | I5: 5441432 | J5: =IFERROR((I5/H5),0) -> 9.5281514 | K5: =I5-F5 -> 3297708 | L5: =(H5-E5)/1000 -> 338.149 | M5: Top 20 | O5: =K5/F5 -> 1.5383081 | P5: =L5/(E5/1000) -> 1.4516508 | R5: Gaurav
A6: AADI_SHAKTI_B2B | B6: New (Aug) | C6: PUMA_SPORT_B2B | D6: PUMA SPORTS INDIA PRIVATE LIMITED | E6: 421570 | F6: 3558786 | G6: =IFERROR((F6/E6),0) -> 8.441744 | H6: 785133 | I6: 5943354 | J6: =IFERROR((I6/H6),0) -> 7.5698691 | K6: =I6-F6 -> 2384568 | L6: =(H6-E6)/1000 -> 363.563 | M6: Top 20 | O6: =K6/F6 -> 0.67005097 | P6: =L6/(E6/1000) -> 0.86240245 | R6: Anjali | T6: 0 | U6: 0 | V6: =IFERROR((U6/T6),0) -> 0 | W6: =F6-U6 -> 3558786 | X6: =W6/F6 -> 1
A7: AAJ_ENTERPRISES_B2B | B7: New July'24 | C7: Signify_East_Secondary_B2B | D7: SIGNIFY INNOVATIONS INDIA LIMITED | E7: 209217 | F7: 2038340 | G7: =IFERROR((F7/E7),0) -> 9.7427073 | H7: 404357 | I7: 3529964 | J7: =IFERROR((I7/H7),0) -> 8.7298204 | K7: =I7-F7 -> 1491624 | L7: =(H7-E7)/1000 -> 195.14 | M7: Top 20 | O7: =K7/F7 -> 0.73178371 | P7: =L7/(E7/1000) -> 0.93271579 | R7: Tasleem | T7: 0 | U7: 0 | V7: =IFERROR((U7/T7),0) -> 0 | W7: =F7-U7 -> 2038340 | X7: =W7/F7 -> 1
A8: AANSWR_FASHION_B2B | B8: - | C8: Pageindustries_Hoskote_B2B | D8: Page Industries Limited | E8: 0 | F8: 0 | G8: =IFERROR((F8/E8),0) -> 0 | H8: 190276 | I8: 1429574 | J8: =IFERROR((I8/H8),0) -> 7.5131598 | K8: =I8-F8 -> 1429574 | L8: =(H8-E8)/1000 -> 190.276 | M8: Top 20 | O8: =K8/F8 -> #DIV/0! | P8: =L8/(E8/1000) -> #DIV/0! | R8: Keshav | T8: 4237 | U8: 64571 | V8: =IFERROR((U8/T8),0) -> 15.239792 | W8: =F8-U8 -> -64571 | X8: =W8/F8 -> #DIV/0!
A9: ABHAY_TECHNO_B2B | B9: - | C9: Himalaya_FG_B2B | D9: HIMALAYA WELLNESS COMPANY | E9: 98329 | F9: 685978.2 | G9: =IFERROR((F9/E9),0) -> 6.9763569 | H9: 250721 | I9: 1905884 | J9: =IFERROR((I9/H9),0) -> 7.6016129 | K9: =I9-F9 -> 1219905.8 | L9: =(H9-E9)/1000 -> 152.392 | M9: Top 20 | O9: =K9/F9 -> 1.7783449 | P9: =L9/(E9/1000) -> 1.5498174 | R9: Keshav | T9: 110 | U9: 1400 | V9: =IFERROR((U9/T9),0) -> 12.727273 | W9: =F9-U9 -> 684578.2 | X9: =W9/F9 -> 0.99795912
A10: AbrosSports_B2B | B10: New client (Jul'26) | C10: TURTLE_B2B | D10: Turtle Limited | E10: 3601 | F10: 46288.03 | G10: =IFERROR((F10/E10),0) -> 12.854215 | H10: 128252 | I10: 1180349 | J10: =IFERROR((I10/H10),0) -> 9.2033575 | K10: =I10-F10 -> 1134061 | L10: =(H10-E10)/1000 -> 124.651 | M10: Top 20 | O10: =K10/F10 -> 24.500091 | P10: =L10/(E10/1000) -> 34.615662 | R10: Pallavi | T10: 0 | U10: 0 | V10: =IFERROR((U10/T10),0) -> 0 | W10: =F10-U10 -> 46288.03 | X10: =W10/F10 -> 1
A11: ACCUMAX_LAB_B2B | B11: New client (Aug'26) | C11: TITAN_WAT_BNG_B2B | D11: TITAN COMPANY LIMITED | E11: 0 | F11: 0 | G11: =IFERROR((F11/E11),0) -> 0 | H11: 99810 | I11: 1089887 | J11: =IFERROR((I11/H11),0) -> 10.919617 | K11: =I11-F11 -> 1089887 | L11: =(H11-E11)/1000 -> 99.81 | M11: - | O11: =K11/F11 -> #DIV/0! | P11: =L11/(E11/1000) -> #DIV/0! | R11: Balu | T11: 1134 | U11: 8604 | V11: =IFERROR((U11/T11),0) -> 7.5873016 | W11: =F11-U11 -> -8604 | X11: =W11/F11 -> #DIV/0!
A12: ACEFOUR_ACCESSORIES_B2B | B12: - | C12: REDTAPE_B2B | D12: REDTAPE LIMITED | E12: 16160 | F12: 309341.9 | G12: =IFERROR((F12/E12),0) -> 19.142444 | H12: 82205 | I12: 1270466 | J12: =IFERROR((I12/H12),0) -> 15.454851 | K12: =I12-F12 -> 961124.1 | L12: =(H12-E12)/1000 -> 66.045 | M12: Top 20 | O12: =K12/F12 -> 3.1069962 | P12: =L12/(E12/1000) -> 4.0869431 | R12: Tasleem | T12: 0 | U12: 0 | V12: =IFERROR((U12/T12),0) -> 0 | W12: =F12-U12 -> 309341.9 | X12: =W12/F12 -> 1
A13: Adidas_B2B | B13: New client (Jan'25) | C13: SOUTHERN HEALTH_B2B | D13: SOUTHERN HEALTH FOODS PRIVATE LIMITED | E13: 14616 | F13: 239584.9 | G13: =IFERROR((F13/E13),0) -> 16.391961 | H13: 74641 | I13: 1034801 | J13: =IFERROR((I13/H13),0) -> 13.863708 | K13: =I13-F13 -> 795216.1 | L13: =(H13-E13)/1000 -> 60.025 | M13: Top 20 | O13: =K13/F13 -> 3.3191411 | P13: =L13/(E13/1000) -> 4.1068008 | R13: Padma | T13: 7836 | U13: 134797 | V13: =IFERROR((U13/T13),0) -> 17.202272 | W13: =F13-U13 -> 104787.9 | X13: =W13/F13 -> 0.43737272
A14: ADITYA_ENTERPRISES_B2B | B14: New client (Aug'26) | C14: BERSACHE_B2B | D14: BERSACHE SPORTS INTERNATIONAL PRIVATE LIMITED | E14: 0 | F14: 0 | G14: =IFERROR((F14/E14),0) -> 0 | H14: 100286 | I14: 733820 | J14: =IFERROR((I14/H14),0) -> 7.3172726 | K14: =I14-F14 -> 733820 | L14: =(H14-E14)/1000 -> 100.286 | M14: - | O14: =K14/F14 -> #DIV/0! | P14: =L14/(E14/1000) -> #DIV/0! | R14: Avinash
A15: Aditya _Infotech_B2b | B15: New client (Aug'26) | C15: DOT_KEY_B2B | D15: DOT & KEY WELLNESS LIMITED | E15: 0 | F15: 0 | G15: =IFERROR((F15/E15),0) -> 0 | H15: 59331 | I15: 661879 | J15: =IFERROR((I15/H15),0) -> 11.155703 | K15: =I15-F15 -> 661879 | L15: =(H15-E15)/1000 -> 59.331 | M15: - | O15: =K15/F15 -> #DIV/0! | P15: =L15/(E15/1000) -> #DIV/0! | R15: Saud
A16: AdityaBirlaFashion_b2b | B16: New client (Jul'26) | C16: JUPITER_LAMINATORS_B2B | D16: JUPITER LAMINATORS PRIVATE LIMITED | E16: 7745 | F16: 66451.09 | G16: =IFERROR((F16/E16),0) -> 8.5798696 | H16: 75506 | I16: 724199 | J16: =IFERROR((I16/H16),0) -> 9.5912775 | K16: =I16-F16 -> 657747.91 | L16: =(H16-E16)/1000 -> 67.761 | M16: Top 20 | O16: =K16/F16 -> 9.898226 | P16: =L16/(E16/1000) -> 8.7489994 | R16: Sudhanshu | T16: 15883 | U16: 241496 | V16: =IFERROR((U16/T16),0) -> 15.204684 | W16: =F16-U16 -> -175044.91 | X16: =W16/F16 -> -2.6341917
A17: ADL_International_B2B | B17: - | C17: Bombay_Wheels_B2B | D17: BOMBAY WHEELS | E17: 5908 | F17: 111713.7 | G17: =IFERROR((F17/E17),0) -> 18.908886 | H17: 39701 | I17: 736967 | J17: =IFERROR((I17/H17),0) -> 18.562933 | K17: =I17-F17 -> 625253.3 | L17: =(H17-E17)/1000 -> 33.793 | M17: Top 20 | O17: =K17/F17 -> 5.5969259 | P17: =L17/(E17/1000) -> 5.7198714 | R17: Deepak Jha | T17: 0 | U17: 0 | V17: =IFERROR((U17/T17),0) -> 0 | W17: =F17-U17 -> 111713.7 | X17: =W17/F17 -> 1
A18: AETRIO_TECHNOLOGY_B2B | B18: New client (Feb'26) | C18: Schneider_B2B | D18: Schneider Electric Private Limited | E18: 0 | F18: 0 | G18: =IFERROR((F18/E18),0) -> 0 | H18: 101449 | I18: 584941 | J18: =IFERROR((I18/H18),0) -> 5.7658627 | K18: =I18-F18 -> 584941 | L18: =(H18-E18)/1000 -> 101.449 | M18: Top 20 | O18: =K18/F18 -> #DIV/0! | P18: =L18/(E18/1000) -> #DIV/0! | R18: Padma | T18: 0 | U18: 0 | V18: =IFERROR((U18/T18),0) -> 0 | W18: =F18-U18 -> 0 | X18: =W18/F18 -> #DIV/0!
A19: AFFINITY_B2B | B19: New client (Aug'26) | C19: KONICA_CHN_PRN_B2B | D19: KONICA MINOLTA BUSINESS SOLUTIONS INDIA PRIVATE LIMITED | E19: 0 | F19: 0 | G19: =IFERROR((F19/E19),0) -> 0 | H19: 32762 | I19: 553953 | J19: =IFERROR((I19/H19),0) -> 16.9084 | K19: =I19-F19 -> 553953 | L19: =(H19-E19)/1000 -> 32.762 | M19: - | O19: =K19/F19 -> #DIV/0! | P19: =L19/(E19/1000) -> #DIV/0! | R19: Pramod | T19: 370 | U19: 14139 | V19: =IFERROR((U19/T19),0) -> 38.213514 | W19: =F19-U19 -> -14139 | X19: =W19/F19 -> #DIV/0!
A20: AGILITAS_B2B | B20: New client (Feb'26) | C20: BATA_B2B | D20: BATA INDIA LIMITED | E20: 2787 | F20: 67335 | G20: =IFERROR((F20/E20),0) -> 24.160388 | H20: 98230 | I20: 595525 | J20: =IFERROR((I20/H20),0) -> 6.0625573 | K20: =I20-F20 -> 528190 | L20: =(H20-E20)/1000 -> 95.443 | M20: Top 20 | O20: =K20/F20 -> 7.8442118 | P20: =L20/(E20/1000) -> 34.245784 | R20: Gaurav | T20: 20840 | U20: 230090 | V20: =IFERROR((U20/T20),0) -> 11.040787 | W20: =F20-U20 -> -162755 | X20: =W20/F20 -> -2.4170936
A21: AIRMAIL_B2B | B21: New client (Jul'26) | C21: FMI_LTD_B2B | D21: FMI LTD | E21: 52179 | F21: 425263 | G21: =IFERROR((F21/E21),0) -> 8.1500795 | H21: 118964 | I21: 935853 | J21: =IFERROR((I21/H21),0) -> 7.8666908 | K21: =I21-F21 -> 510590 | L21: =(H21-E21)/1000 -> 66.785 | M21: Top 20 | O21: =K21/F21 -> 1.2006452 | P21: =L21/(E21/1000) -> 1.279921 | R21: Raj Kamal | T21: 0 | U21: 1416 | V21: =IFERROR((U21/T21),0) -> 0 | W21: =F21-U21 -> 423847 | X21: =W21/F21 -> 0.9966703
A22: AJANTA_SHOES_B2B | B22: New client (Mar'26) | C22: JAMBULOGIX_B2B | D22: JAMBULOGIX PRIVATE LIMITED | E22: 104435 | F22: 1235627 | G22: =IFERROR((F22/E22),0) -> 11.831541 | H22: 140818 | I22: 1733732 | J22: =IFERROR((I22/H22),0) -> 12.311864 | K22: =I22-F22 -> 498105 | L22: =(H22-E22)/1000 -> 36.383 | M22: Top 20 | O22: =K22/F22 -> 0.40311923 | P22: =L22/(E22/1000) -> 0.34837937 | R22: Deepak Jha | T22: 3000 | U22: 44332 | V22: =IFERROR((U22/T22),0) -> 14.777333 | W22: =F22-U22 -> 1191295 | X22: =W22/F22 -> 0.96412186 | Y22: top 20
A23: ALPINO_B2B | B23: New client (Aug'26) | C23: BOLDFIT_B2B | D23: BLING BRANDS PRIVATE LIMITED | E23: 0 | F23: 0 | G23: =IFERROR((F23/E23),0) -> 0 | H23: 48784 | I23: 491395 | J23: =IFERROR((I23/H23),0) -> 10.072872 | K23: =I23-F23 -> 491395 | L23: =(H23-E23)/1000 -> 48.784 | M23: - | O23: =K23/F23 -> #DIV/0! | P23: =L23/(E23/1000) -> #DIV/0! | R23: Deepak | T23: 0 | U23: 0 | V23: =IFERROR((U23/T23),0) -> 0 | W23: =F23-U23 -> 0 | X23: =W23/F23 -> #DIV/0!
A24: AMAR_BIO_B2B | B24: New client (Jan'26) | C24: OLA_B2B | D24: Ola Electric Technologies Private Limited | E24: 298543 | F24: 4269549 | G24: =IFERROR((F24/E24),0) -> 14.301287 | H24: 373314 | I24: 4754392 | J24: =IFERROR((I24/H24),0) -> 12.735638 | K24: =I24-F24 -> 484843 | L24: =(H24-E24)/1000 -> 74.771 | M24: Top 20 | O24: =K24/F24 -> 0.11355836 | P24: =L24/(E24/1000) -> 0.25045303 | R24: Keshav | T24: 3499 | U24: 114331 | V24: =IFERROR((U24/T24),0) -> 32.675336 | W24: =F24-U24 -> 4155218 | X24: =W24/F24 -> 0.97322176
A25: AMLANI_B2B | B25: New client (Jan'26) | C25: Bharatpe_B2B | D25: RESILIENT INNOVATIONS PRIVATE LIMITED | E25: 8295 | F25: 143708.4 | G25: =IFERROR((F25/E25),0) -> 17.324702 | H25: 36512 | I25: 594291 | J25: =IFERROR((I25/H25),0) -> 16.276594 | K25: =I25-F25 -> 450582.6 | L25: =(H25-E25)/1000 -> 28.217 | M25: Top 20 | O25: =K25/F25 -> 3.135395 | P25: =L25/(E25/1000) -> 3.4016878 | R25: Deepak Jha | T25: 0 | U25: 0 | V25: =IFERROR((U25/T25),0) -> 0 | W25: =F25-U25 -> 143708.4 | X25: =W25/F25 -> 1
A26: Amruta_Herbals_B2B | B26: New client (May'26) | C26: RELIABLE_B2B | D26: RELIABLE INTERNATIONAL | E26: 214 | F26: 5592.2 | G26: =IFERROR((F26/E26),0) -> 26.131776 | H26: 42335 | I26: 440669 | J26: =IFERROR((I26/H26),0) -> 10.409094 | K26: =I26-F26 -> 435076.8 | L26: =(H26-E26)/1000 -> 42.121 | M26: Top 20 | O26: =K26/F26 -> 77.800651 | P26: =L26/(E26/1000) -> 196.8271 | R26: Rahul | T26: 0 | U26: 0 | V26: =IFERROR((U26/T26),0) -> 0 | W26: =F26-U26 -> 5592.2 | X26: =W26/F26 -> 1
A27: Amul_Macho_B2B | B27: New client (Aug'25) | C27: DUKE_FASHIONS_B2B | D27: DUKE FASHION INDIA LTD | E27: 20451 | F27: 275460.6 | G27: =IFERROR((F27/E27),0) -> 13.469297 | H27: 45655 | I27: 700051 | J27: =IFERROR((I27/H27),0) -> 15.333501 | K27: =I27-F27 -> 424590.4 | L27: =(H27-E27)/1000 -> 25.204 | M27: Top 20 | O27: =K27/F27 -> 1.5413834 | P27: =L27/(E27/1000) -> 1.2324092 | R27: Deepak Jha | T27: 0 | U27: 0 | V27: =IFERROR((U27/T27),0) -> 0 | W27: =F27-U27 -> 275460.6 | X27: =W27/F27 -> 1
A28: Apollosupplychain_B2B | B28: New client (Aug'26) | C28: MOUNTHILLS_B2B | D28: Mounthills Incorporation | E28: 0 | F28: 0 | G28: =IFERROR((F28/E28),0) -> 0 | H28: 39114 | I28: 408365 | J28: =IFERROR((I28/H28),0) -> 10.440379 | K28: =I28-F28 -> 408365 | L28: =(H28-E28)/1000 -> 39.114 | M28: - | O28: =K28/F28 -> #DIV/0! | P28: =L28/(E28/1000) -> #DIV/0! | R28: Kaushal | T28: 1874 | U28: 54572 | V28: =IFERROR((U28/T28),0) -> 29.120598 | W28: =F28-U28 -> -54572 | X28: =W28/F28 -> #DIV/0!
A29: Argo_Retail_B2B | B29: New client (Nov'25) | C29: METRO_ECOM_B2B | D29: Metro Brands Limited | E29: 85546 | F29: 1093123 | G29: =IFERROR((F29/E29),0) -> 12.77819 | H29: 47672 | I29: 1484018 | J29: =IFERROR((I29/H29),0) -> 31.129762 | K29: =I29-F29 -> 390895 | L29: =(H29-E29)/1000 -> -37.874 | M29: Top 20 | O29: =K29/F29 -> 0.35759471 | P29: =L29/(E29/1000) -> -0.44273256 | R29: Pratik
A30: ARSH_EXPRESS_B2B | B30: New client (Aug'26) | C30: ROTECH_HEALTHCARE_B2B | D30: ROTECH_HEALTHCARE_B2B | E30: 0 | F30: 0 | G30: =IFERROR((F30/E30),0) -> 0 | H30: 41808 | I30: 388294 | J30: =IFERROR((I30/H30),0) -> 9.2875526 | K30: =I30-F30 -> 388294 | L30: =(H30-E30)/1000 -> 41.808 | M30: - | O30: =K30/F30 -> #DIV/0! | P30: =L30/(E30/1000) -> #DIV/0! | R30: Aman | T30: 175731 | U30: 2219326 | V30: =IFERROR((U30/T30),0) -> 12.629109 | W30: =F30-U30 -> -2219326 | X30: =W30/F30 -> #DIV/0!
A31: ARV_INDUSTRIES_B2B | B31: New client (Jul'26) | C31: CDS_LOGISTICS_B2B | D31: CDS LOGISTICS | E31: 16631 | F31: 176026.9 | G31: =IFERROR((F31/E31),0) -> 10.584264 | H31: 58309 | I31: 563617 | J31: =IFERROR((I31/H31),0) -> 9.6660378 | K31: =I31-F31 -> 387590.1 | L31: =(H31-E31)/1000 -> 41.678 | M31: - | O31: =K31/F31 -> 2.2018799 | P31: =L31/(E31/1000) -> 2.5060429 | R31: Rahul | T31: 0 | U31: 0 | V31: =IFERROR((U31/T31),0) -> 0 | W31: =F31-U31 -> 176026.9 | X31: =W31/F31 -> 1
A32: ASHANA_B2B | B32: New client (Feb'26) | C32: KORES_INBOUND_B2B | D32: KORES INDIA LIMITED | E32: 48329 | F32: 655163.8 | G32: =IFERROR((F32/E32),0) -> 13.556328 | H32: 72941 | I32: 1035149 | J32: =IFERROR((I32/H32),0) -> 14.191593 | K32: =I32-F32 -> 379985.2 | L32: =(H32-E32)/1000 -> 24.612 | M32: - | O32: =K32/F32 -> 0.57998504 | P32: =L32/(E32/1000) -> 0.50925945 | R32: Aditi | T32: 0 | U32: 0 | V32: =IFERROR((U32/T32),0) -> 0 | W32: =F32-U32 -> 655163.8 | X32: =W32/F32 -> 1
A33: Asia_Parcel_B2B | B33: New (Aug) | C33: ATMOS_CARE_B2B | D33: ATMOS CARE PRIVATE LIMITED | E33: 204013 | F33: 2412711 | G33: =IFERROR((F33/E33),0) -> 11.826261 | H33: 236801 | I33: 2750762 | J33: =IFERROR((I33/H33),0) -> 11.616345 | K33: =I33-F33 -> 338051 | L33: =(H33-E33)/1000 -> 32.788 | M33: - | O33: =K33/F33 -> 0.14011251 | P33: =L33/(E33/1000) -> 0.16071525 | R33: Harisha | T33: 2851 | U33: 31877 | V33: =IFERROR((U33/T33),0) -> 11.180989 | W33: =F33-U33 -> 2380834 | X33: =W33/F33 -> 0.98678789
A34: ASIAN_FOOTWEARS_B2B | B34: New client (Aug'26) | C34: SUN_ORGANIC_B2B | D34: SUN ORGANIC INDUSTRIES PRIVATE LIMITED | E34: 0 | F34: 0 | G34: =IFERROR((F34/E34),0) -> 0 | H34: 34901 | I34: 310706 | J34: =IFERROR((I34/H34),0) -> 8.9024956 | K34: =I34-F34 -> 310706 | L34: =(H34-E34)/1000 -> 34.901 | M34: - | O34: =K34/F34 -> #DIV/0! | P34: =L34/(E34/1000) -> #DIV/0! | R34: Sudhanshu | T34: 9664 | U34: 119081 | V34: =IFERROR((U34/T34),0) -> 12.322123 | W34: =F34-U34 -> -119081 | X34: =W34/F34 -> #DIV/0!
A35: ASIAN_RETAIL_B2B | B35: New client (Jul'26) | C35: SME_EXPRESS_B2B | D35: SME EXPRESS | E35: 38974 | F35: 429050.7 | G35: =IFERROR((F35/E35),0) -> 11.008639 | H35: 64967 | I35: 737724 | J35: =IFERROR((I35/H35),0) -> 11.355365 | K35: =I35-F35 -> 308673.3 | L35: =(H35-E35)/1000 -> 25.993 | M35: - | O35: =K35/F35 -> 0.71943316 | P35: =L35/(E35/1000) -> 0.6669318 | R35: Balu | T35: 1915 | U35: 19059 | V35: =IFERROR((U35/T35),0) -> 9.9524804 | W35: =F35-U35 -> 409991.7 | X35: =W35/F35 -> 0.95557868 | Y35: top 20
A36: ASMR_BITES_B2B | B36: New client (Feb'26) | C36: THE_WOOD_WHITE_B2B | D36: THE WOOD WHITE INDIA | E36: 4107 | F36: 140898.7 | G36: =IFERROR((F36/E36),0) -> 34.306964 | H36: 28847 | I36: 447741 | J36: =IFERROR((I36/H36),0) -> 15.521233 | K36: =I36-F36 -> 306842.3 | L36: =(H36-E36)/1000 -> 24.74 | M36: - | O36: =K36/F36 -> 2.1777511 | P36: =L36/(E36/1000) -> 6.0238617 | R36: Pooja
A37: ATMOS_CARE_B2B | B37: New client (Jul'26) | C37: METRO_RETAIL_B2B | D37: Metro Retail | E37: 98767 | F37: 920659.9 | G37: =IFERROR((F37/E37),0) -> 9.3215335 | H37: 126179 | I37: 1222905 | J37: =IFERROR((I37/H37),0) -> 9.6918267 | K37: =I37-F37 -> 302245.1 | L37: =(H37-E37)/1000 -> 27.412 | M37: - | O37: =K37/F37 -> 0.3282918 | P37: =L37/(E37/1000) -> 0.27754209 | R37: Saud
A38: AUSTRALIAN_FOODS_B2B | B38: New client (Jan'26) | C38: JQR_B2B | D38: JQR SPORTS (INDIA) PRIVATE LIMITED | E38: 119203 | F38: 1281363 | G38: =IFERROR((F38/E38),0) -> 10.749419 | H38: 133584 | I38: 1574464 | J38: =IFERROR((I38/H38),0) -> 11.786322 | K38: =I38-F38 -> 293101 | L38: =(H38-E38)/1000 -> 14.381 | M38: - | O38: =K38/F38 -> 0.22874158 | P38: =L38/(E38/1000) -> 0.12064294 | R38: Tasleem | T38: 0 | U38: 0 | V38: =IFERROR((U38/T38),0) -> 0 | W38: =F38-U38 -> 1281363 | X38: =W38/F38 -> 1
A39: AWESOMEFAB_B2B | B39: New client (Mar'26) | C39: LAZER_B2B | D39: LAZER INDIA PRIVATE LIMITED | E39: 25666 | F39: 238275.7 | G39: =IFERROR((F39/E39),0) -> 9.28371 | H39: 50333 | I39: 499492 | J39: =IFERROR((I39/H39),0) -> 9.9237478 | K39: =I39-F39 -> 261216.3 | L39: =(H39-E39)/1000 -> 24.667 | M39: - | O39: =K39/F39 -> 1.0962775 | P39: =L39/(E39/1000) -> 0.96107691 | R39: Sudhanshu | T39: 69 | U39: 1243 | V39: =IFERROR((U39/T39),0) -> 18.014493 | W39: =F39-U39 -> 237032.7 | X39: =W39/F39 -> 0.99478335 | Y39: Near churn
A40: B_JAIN_PHARMA_B2B | B40: New client (Feb'26) | C40: SHREE_KARNI_B2B | D40: SHREE KARNI KRIPAA ENTERPRISES | E40: 74886 | F40: 1271982 | G40: =IFERROR((F40/E40),0) -> 16.985578 | H40: 110756 | I40: 1531762 | J40: =IFERROR((I40/H40),0) -> 13.830059 | K40: =I40-F40 -> 259780 | L40: =(H40-E40)/1000 -> 35.87 | M40: - | O40: =K40/F40 -> 0.20423245 | P40: =L40/(E40/1000) -> 0.47899474 | R40: Pooja
...

Sheet Sheet1

Sheet master
J1: 10-07-202612:15 | K1: Live | L1: code | M1: Client | N1: kam
B2: Bill to Business | C2: Legal Name | D2: onboarding month | E2: BD | F2: KAM | G2: Region | K2: New client (May'26) | L2: MANASH_AD_B2B | M2: MANASH LIFESTYLE PRIVATE LIMITED | N2: Avinash
B3: 1MG_B2B | C3: TATA 1MG HEALTHCARE SOLUTIONS PRIVATE LIMITED | D3: New client (Mar'26) | E3: Avinash | F3: Avinash | G3: North | K3: New client (Jun'26) | L3: VIP_B2B | M3: VIP INDUSTRIES LIMITED | N3: Saud
B4: 4TH_PHARMA_B2B | C4: 4THD PHARMA PRIVATE LIMITED | D4: New client (Mar'26) | E4: Rahul | F4: Rahul | G4: North | K4: New client (jun'25) | L4: PUREPLAY_B2B | M4: PUREPLAY SKIN SCIENCES (INDIA) PRIVATE LIMITED | N4: Pratik
B5: 6HEIGHT_B2B | C5: 6HEIGHT TRANS SOLUTIONS PRIVATE LIMITED | D5: New client (Nov'25) | E5: Pramod | F5: Pramod | G5: North | K5: - | L5: PICKRR_B2B | M5: Pickrr Technologies Private Limited | N5: Amit
B6: AADI_SHAKTI_B2B | C6: AADI SHAKTI ENTERPRISES | D6: New client (Jun'26) | E6: Sanchit | F6: Sanchit | G6: North | K6: New (Aug) | L6: AbrosSports_B2B | M6: ABROS SPORTS INTERNATIONAL PRIVATE LIMITED | N6: Vandana
B7: AAJ_ENTERPRISES_B2B | C7: AAJ SUPPLY CHAIN MANAGEMENT PRIVATE LIMITED | D7: New(Jan) | E7: Deepika | F7: Avinash | G7: North | K7: New (Aug) | L7: ATMOS_CARE_B2B | M7: ATMOS CARE PRIVATE LIMITED | N7: Deepak
B8: AANSWR_FASHION_B2B | C8: AANSWR FASHION PRIVATE LIMITED | D8: New client (Apr'26) | E8: Deepak | F8: Deepak | G8: South | K8: New client (Jun'26) | L8: MEDITREE_AMD_B2B | M8: MEDITREE LIFECARE LLP | N8: Shekhar
B9: ABHAY_TECHNO_B2B | C9: ABHAY TECHNO SERVICES PRIVATE LIMITED | D9: New client (Jan'26) | E9: Aman | F9: Aman | G9: North | K9: - | L9: LIGHTHOUSE_B2B | M9: Lighthouse Learning Private Limited | N9: Harshith S
B10: AbrosSports_B2B | C10: ABROS SPORTS INTERNATIONAL PRIVATE LIMITED | D10: New (Aug) | E10: Mohit | F10: Vandana | G10: North | K10: New client (Jun'26) | L10: NURECA_LIMITED_B2B | M10: NURECA LIMITED | N10: Raj Kamal
B11: ACCUMAX_LAB_B2B | C11: ACCUMAX LAB DEVICES PRIVATE LIMITED | D11: New client (Jun'26) | E11: Soumya | F11: Soumya | G11: West | K11: New client (Feb'26) | L11: SHREE_KARNI_B2B | M11: SHREE KARNI KRIPAA ENTERPRISES | N11: Pooja
B12: ACEFOUR_ACCESSORIES_B2B | C12: ACEFOUR ACCESSORIES PRIVATE LIMITED | D12: New(Jan) | E12: Gaurav Narayan | F12: Pratik | G12: West | K12: - | L12: GlobalBees_B2B | M12: MERHAKI FOODS AND NUTRITION PRIVATE LIMITED | N12: Amit
B13: Adidas_B2B | C13: ADIDAS INDIA MARKETING PRIVATE LIMITED | D13: New client (Jan'26) | E13: Tasleem | F13: Avinash | G13: North | K13: New client (Jun'26) | L13: B_VISHAL_CORP_B2B | M13: B. VISHAL CORPORATION | N13: Pratik
... B403: ZIVORE_B2B | C403: ZIVORE APPAREL PRIVATE LIMITED | D403: New client (May'26) | E403: Sanchit | F403: Sanchit | G403: North | K403: revival (Jun'26) | L403: vanheusen_NEL_B2B | M403: ADITYA BIRLA LIFESTYLE BRANDS LIMITED | N403: Harisha
K404: New client (May'26) | L404: KEVA_KAIPO_B2B | M404: KEVA KAIPO INDUSTRIES PRIVATE LIMITED | N404: Raj Kamal
K405: new client (Dec'25) | L405: CREATIVE_B2B | M405: CREATIVE GALILEO EDTECH PRIVATE LIMITED | N405: Deepak Jha
K406: New client (April26) | L406: KUMAR_CAR_BANGALORE_B2B | M406: C TRACK AUTO INDUSTRIES | N406: Anbu
K407: new client(march'25) | L407: MANGLA_B2B | M407: MANGLA APPARELS INDIA PRIVATE LIMITED | N407: Tasleem
K408: New client (Feb'26) | L408: TRADE_FT_B2B | M408: TradeFT Enterprises | N408: Deepak Jha
K409: New client (Jun'26) | L409: NUMAX_ENERGY_B2B | M409: NUMAX ENERGY SOLUTIONS | N409: Subhash
K410: New client (Oct'25) | L410: HK_DATA_B2B | M410: H K DATA SERVICES PRIVATE LIMITED | N410: Pratik
K411: New client (Jan'26) | L411: ABHAY_TECHNO_B2B | M411: ABHAY TECHNO SERVICES PRIVATE LIMITED | N411: Deepak Jha
K412: New client (Jan'26) | L412: KOMFORT_B2B | M412: KOMFORT CREATIONS | N412: Deepak Jha
K413: New may'25 | L413: HANDY_HOME_B2B | M413: HANDY HOME SOLUTIONS PRIVATE LIMITED | N413: Deepak Jha
K414: New client (Jun'26) | L414: RISO_B2B | M414: RISO INDIA PRIVATE LIMITED | N414: Pramod
K415: New(Feb) | L415: GLADPACK_B2B | M415: GLADPACK | N415: Deepak Jha
... K422: New client (Apr'26) | L422: LINC_PEN_B2B | M422: LINC LIMITED | N422: Pallavi

Sheet MAPPING
E1: For Apr file
C2: MAPPED CODE | D2: Client | F2: MAPPED CODE | G2: Client | K2: Client code | L2: Client name | M2: Launch year | N2: kam | X2: code | Y2: Client | Z2: Aug Final chargeable weight | AA2: Aug Total Revenue
C3: PICKRR_B2B | D3: PICKRR TECHNOLOGIES PVT LTD | F3: PICKRR_B2B | G3: PICKRR TECHNOLOGIES PVT LTD | K3: Raymond_Ltd_B2B | L3: RAYMOND LIFESTYLE LIMITED | M3: - | N3: Vandana | X3: =_xlfn.XLOOKUP(Y3,master!M:M,master!L:L) -> MANASH_AD_B2B | Y3: MANASH LIFESTYLE PRIVATE LIMITED | Z3: 500465 | AA3: 5320500 | AB3: =COUNTIFS(Base!$C:$C,MAPPING!X3) -> 1
C4: Signify_Innovations_B2B | D4: SIGNIFY INNOVATIONS INDIA LIMITED | F4: Signify_Innovations_B2B | G4: SIGNIFY INNOVATIONS INDIA LIMITED | K4: School_shop_B2B | L4: SCHOOL SHOP PRIVATE LIMITED | M4: - | N4: Balu | X4: =_xlfn.XLOOKUP(Y4,master!M:M,master!L:L) -> Raymond_Home_Ltd_B2B | Y4: RAYMOND LIFESTYLE LIMITED | Z4: 361749 | AA4: 12830806 | AB4: =COUNTIFS(Base!$C:$C,MAPPING!X4) -> 1
C5: GodrejBoyce_B2B | D5: GODREJ AND BOYCE MGF CO LIMITED | F5: GodrejBoyce_B2B | G5: GODREJ AND BOYCE MGF CO LIMITED | K5: OLA_B2B | L5: Ola Electric Technologies Private Limited | M5: New client (Jan'26) | N5: Balu | X5: =_xlfn.XLOOKUP(Y5,master!M:M,master!L:L) -> AbrosSports_B2B | Y5: ABROS SPORTS INTERNATIONAL PRIVATE LIMITED | Z5: 119504 | AA5: 3663682 | AB5: =COUNTIFS(Base!$C:$C,MAPPING!X5) -> 1
C6: GlobalBees_B2B | D6: MERHAKI FOODS AND NUTRITION PRIVATE LIMITED | F6: GlobalBees_B2B | G6: MERHAKI FOODS AND NUTRITION PRIVATE LIMITED | K6: AbrosSports_B2B | L6: ABROS SPORTS INTERNATIONAL PRIVATE LIMITED | M6: New (Aug) | N6: Vandana | X6: =_xlfn.XLOOKUP(Y6,master!M:M,master!L:L) -> OLA_B2B | Y6: OLA ELECTRIC TECHNOLOGIES PRIVATE LIMITED | Z6: 373314 | AA6: 4754392 | AB6: =COUNTIFS(Base!$C:$C,MAPPING!X6) -> 1
C7: AbrosSports_B2B | D7: ABROS SPORTS INTERNATIONAL PRIVATE LIMITED | F7: AbrosSports_B2B | G7: ABROS SPORTS INTERNATIONAL PRIVATE LIMITED | K7: Yolojet_Internet_Services_Private_Limited_B2B | L7: Yolojet Internet Services Private Limited | M7: New(dec) | N7: Deepak | X7: =_xlfn.XLOOKUP(Y7,master!M:M,master!L:L) -> CULTSPORT_B2B | Y7: CULTSPORT PRIVATE LIMITED | Z7: 194635 | AA7: 3174783 | AB7: =COUNTIFS(Base!$C:$C,MAPPING!X7) -> 1
C8: Adityabirlafashion_b2b | D8: ADITYA BIRLA FASHION AND RETAIL LIMITED | F8: Adityabirlafashion_b2b | G8: ADITYA BIRLA FASHION AND RETAIL LIMITED | K8: CULTSPORT_B2B | L8: CULTSPORT PRIVATE LIMITED | M8: New client (Aug'25) | N8: Balu | X8: =_xlfn.XLOOKUP(Y8,master!M:M,master!L:L) -> PICKRR_B2B | Y8: Pickrr Technologies Private Limited | Z8: 359571 | AA8: 4212428 | AB8: =COUNTIFS(Base!$C:$C,MAPPING!X8) -> 1
C9: Trumove_B2B | D9: TRUMOVE SERVICES PRIVATE LIMITED | F9: Trumove_B2B | G9: TRUMOVE SERVICES PRIVATE LIMITED | K9: Apollosupplychain_B2B | L9: Apollo Supply Chain Private Limited | M9: - | N9: Aman | X9: =_xlfn.XLOOKUP(Y9,master!M:M,master!L:L) -> Adidas_B2B | Y9: ADIDAS INDIA MARKETING PRIVATE LIMITED | Z9: 168603 | AA9: 2836295 | AB9: =COUNTIFS(Base!$C:$C,MAPPING!X9) -> 1
C10: REDTAPE_B2B | D10: REDTAPE LIMITED | F10: REDTAPE_B2B | G10: REDTAPE LIMITED | K10: MANASH_B2B | L10: MANASH LIFESTYLE PRIVATE LIMITED | M10: New client (May'26) | N10: Avinash | X10: =_xlfn.XLOOKUP(Y10,master!M:M,master!L:L) -> PUMA_SPORT_B2B | Y10: PUMA SPORTS INDIA PRIVATE LIMITED | Z10: 785133 | AA10: 5943354 | AB10: =COUNTIFS(Base!$C:$C,MAPPING!X10) -> 1
C11: Raymond_Ltd_B2B | D11: Raymond Limited | F11: Raymond_Ltd_B2B | G11: Raymond Limited | K11: Micro_Footwear_B2B | L11: MICRO FOOTWEARS PVT. LTD | M11: New(Jan) | N11: Vandana | X11: =_xlfn.XLOOKUP(Y11,master!M:M,master!L:L) -> BENETTON_B2B | Y11: BENETTON INDIA PRIVATE LIMITED | Z11: 177778 | AA11: 2083204 | AB11: =COUNTIFS(Base!$C:$C,MAPPING!X11) -> 1
C12: Bright_Lifecare_B2B | D12: BRIGHT LIFECARE PRIVATE LIMITED | F12: Bright_Lifecare_B2B | G12: BRIGHT LIFECARE PRIVATE LIMITED | K12: Himalaya_RM_B2B | L12: HIMALAYA WELLNESS COMPANY | M12: - | N12: Balu | X12: =_xlfn.XLOOKUP(Y12,master!M:M,master!L:L) -> Yolojet_Internet_Services_Private_Limited_B2B | Y12: Yolojet Internet Services Private Limited | Z12: 185286 | AA12: 2899188 | AB12: =COUNTIFS(Base!$C:$C,MAPPING!X12) -> 1
C13: PUMA_SPORT_B2B | D13: PUMA SPORTS INDIA PRIVATE LIMITED | F13: PUMA_SPORT_B2B | G13: PUMA SPORTS INDIA PRIVATE LIMITED | K13: Modenik_ecom_B2B | L13: MODENIK LIFESTYLE PRIVATE LIMITED | M13: - | N13: Balu | X13: =_xlfn.XLOOKUP(Y13,master!M:M,master!L:L) -> Apollosupplychain_B2B | Y13: Apollo Supply Chain Private Limited | Z13: 156265 | AA13: 2435105 | AB13: =COUNTIFS(Base!$C:$C,MAPPING!X13) -> 1
C14: Prozo_Distribution_B2B | D14: Prozo Distribution Private Limited | F14: Prozo_Distribution_B2B | G14: Prozo Distribution Private Limited | K14: GodrejBoyce_B2B | L14: GODREJ AND BOYCE MANUFACTURING CO LTD. | M14: - | N14: Amit | X14: =_xlfn.XLOOKUP(Y14,master!M:M,master!L:L) -> EurekaForbes_Bangalore_B2B | Y14: EUREKA FORBES LIMITED | Z14: 252306 | AA14: 2802137 | AB14: =COUNTIFS(Base!$C:$C,MAPPING!X14) -> 1
... C44: Icarry_B2B | D44: ICARRY TECHNOLOGIES PRIVATE LIMITED | F44: Icarry_B2B | G44: ICARRY TECHNOLOGIES PRIVATE LIMITED | K44: ACEFOUR_ACCESSORIES_B2B | L44: ACEFOUR ACCESSORIES PRIVATE LIMITED | M44: New(Jan) | N44: Pratik | X44: =_xlfn.XLOOKUP(Y44,master!M:M,master!L:L) -> JINDAL_B2B | Y44: JINDAL FINE INDUSTRIES | Z44: 42986 | AA44: 814335 | AB44: =COUNTIFS(Base!$C:$C,MAPPING!X44) -> 1
C45: Shippingimperio_B2B | D45: SHIPPING IMPERIO PRIVATE LIMITED | F45: Shippingimperio_B2B | G45: SHIPPING IMPERIO PRIVATE LIMITED | K45: MIDLINKERZ_B2B | L45: MIDLINKERZ PRIVATE LIMITED | M45: New(dec) | N45: Tasleem | X45: =_xlfn.XLOOKUP(Y45,[1]rpk!$B:$B,[1]rpk!$A:$A) -> METRO_RETAIL_B2B | Y45: METRO RETAIL PRIVATE LIMITED | Z45: 126179 | AA45: 1222905 | AB45: =COUNTIFS(Base!$C:$C,MAPPING!X45) -> 1
C46: TRANSLOGICS_SOLUTIONS_B2B | D46: TRANSLOGICS SOLUTIONS | F46: TRANSLOGICS_SOLUTIONS_B2B | G46: TRANSLOGICS SOLUTIONS | K46: Globate_360_B2B | L46: GLOBATE 360 SOLUTIONS PRIVATE LIMITED | M46: New(Jan) | N46: Deepika | X46: =_xlfn.XLOOKUP(Y46,master!M:M,master!L:L) -> FAMOUS_ROADLINES_B2B | Y46: FAMOUS ROADLINES | Z46: 29323 | AA46: 328481 | AB46: =COUNTIFS(Base!$C:$C,MAPPING!X46) -> 1
C47: Globate_360_B2B | D47: Globate 360 Solutions pvt ltd | F47: Globate_360_B2B | G47: Globate 360 Solutions pvt ltd | K47: AGILITAS_B2B | L47: AGILITAS BRANDS PRIVATE LIMITED | M47: - | N47: Deepak | X47: =_xlfn.XLOOKUP(Y47,master!M:M,master!L:L) -> RUPA_COMPANY_B2B | Y47: RUPA & COMPANY LIMITED | Z47: 89934 | AA47: 997852 | AB47: =COUNTIFS(Base!$C:$C,MAPPING!X47) -> 1
C48: Palred_Electronics_B2B | D48: PALRED ELECTRONICS PRIVATE LIMITED | F48: Palred_Electronics_B2B | G48: PALRED ELECTRONICS PRIVATE LIMITED | K48: Raymond_Home_Ltd_B2B | L48: RAYMOND LIFESTYLE LIMITED | M48: - | N48: Vandana | X48: =_xlfn.XLOOKUP(Y48,master!M:M,master!L:L) -> MIDLINKERZ_B2B | Y48: MIDLINKERZ PRIVATE LIMITED | Z48: 45480 | AA48: 916431 | AB48: =COUNTIFS(Base!$C:$C,MAPPING!X48) -> 1
C49: Kutchina_B2B | D49: KUTCHINA HOME MAKERS PRIVATE LIMITED | F49: Kutchina_B2B | G49: KUTCHINA HOME MAKERS PRIVATE LIMITED | K49: TECH_ALMOND_B2B | L49: TECH ALMOND SOLUTIONS PRIVATE LIMITED | M49: New client (Apr'26) | N49: Aman | X49: =_xlfn.XLOOKUP(Y49,master!M:M,master!L:L) -> RASHI_PERIPHERALS_B2B | Y49: RASHI PERIPHERALS LIMITED | Z49: 37434 | AA49: 473403 | AB49: =COUNTIFS(Base!$C:$C,MAPPING!X49) -> 1
C50: Happilo_B2B | D50: HAPPILO INTERNATIONAL | F50: Happilo_B2B | G50: HAPPILO INTERNATIONAL | K50: Adidas_B2B | L50: ADIDAS INDIA MARKETING PRIVATE LIMITED | M50: New client (Jan'26) | N50: Avinash | X50: =_xlfn.XLOOKUP(Y50,master!M:M,master!L:L) -> Bolasagro_B2B | Y50: BOLAS AGRO PRIVATE LIMITED | Z50: 65195 | AA50: 854305 | AB50: =COUNTIFS(Base!$C:$C,MAPPING!X50) -> 1
C51: BathlaAluminum_B2B | D51: BATHLA ALUMINIUM PVT LTD | F51: BathlaAluminum_B2B | G51: BATHLA ALUMINIUM PVT LTD | K51: REDTAPE_B2B | L51: REDTAPE LIMITED | M51: - | N51: Avinash | X51: =_xlfn.XLOOKUP(Y51,master!M:M,master!L:L) -> Globate_360_B2B | Y51: GLOBATE 360 SOLUTIONS PRIVATE LIMITED | Z51: 7417 | AA51: 97958 | AB51: =COUNTIFS(Base!$C:$C,MAPPING!X51) -> 1
C52: Street Nine_b2b | D52: STREET NINE FASHIONS PRIVATE LIMITED | F52: Street Nine_b2b | G52: STREET NINE FASHIONS PRIVATE LIMITED | K52: ITHINK_LOGISTIC_B2B | L52: ITHINK LOGISTIC QUICK SERVICES PRIVATE LIMITED | M52: New client (July'25) | N52: pradeep | X52: =_xlfn.XLOOKUP(Y52,master!M:M,master!L:L) -> Indian_Terrain_B2B | Y52: INDIAN TERRAIN FASHIONS LIMITED | Z52: 62713 | AA52: 924968 | AB52: =COUNTIFS(Base!$C:$C,MAPPING!X52) -> 1
C53: NIRVAANIC_B2B | D53: NIRVAANIC LIFE FOODS PRIVATE LIMITED | F53: NIRVAANIC_B2B | G53: NIRVAANIC LIFE FOODS PRIVATE LIMITED | K53: HONASA_B2B | L53: HONASA CONSUMER LIMITED | M53: New client (Feb'26) | N53: Aman | X53: =_xlfn.XLOOKUP(Y53,master!M:M,master!L:L) -> URBAN_STAR_6_B2B | Y53: URBAN STAR GLOBAL SERVICES PRIVATE LIMITED | Z53: 14653 | AA53: 227377 | AB53: =COUNTIFS(Base!$C:$C,MAPPING!X53) -> 1
C54: ACEFOUR_ACCESSORIES_B2B | D54: ACEFOUR ACCESSORIES PRIVATE LIMITED | F54: ACEFOUR_ACCESSORIES_B2B | G54: ACEFOUR ACCESSORIES PRIVATE LIMITED | K54: LAZER_B2B | L54: LAZER INDIA PRIVATE LIMITED | M54: New client (Mar'26) | N54: Sudhanshu | X54: =_xlfn.XLOOKUP(Y54,master!M:M,master!L:L) -> ZIVORE_B2B | Y54: ZIVORE APPAREL PRIVATE LIMITED | Z54: 58426 | AA54: 884880 | AB54: =COUNTIFS(Base!$C:$C,MAPPING!X54) -> 1
C55: AVNBUSINESS_B2B | D55: AVN BUSINESS SOLUTIONS PRIVATE LIMITED | F55: AVNBUSINESS_B2B | G55: AVN BUSINESS SOLUTIONS PRIVATE LIMITED | K55: Argo_Retail_B2B | L55: ARGO TRADING INDIA PRIVATE LIMITED | M55: new client (Jul'25) | N55: Aman | X55: =_xlfn.XLOOKUP(Y55,master!M:M,master!L:L) -> ITHINK_LOGISTIC_B2B | Y55: ITHINK LOGISTIC QUICK SERVICES PRIVATE LIMITED | Z55: 7699 | AA55: 191994 | AB55: =COUNTIFS(Base!$C:$C,MAPPING!X55) -> 1
C56: Warner_B2B | D56: Warner Industries | F56: Warner_B2B | G56: Warner Industries | K56: XYXX_APPARELS_B2B | L56: XYXX APPARELS PRIVATE LIMITED | M56: New client (Apr'26) | N56: Deepak | X56: =_xlfn.XLOOKUP(Y56,master!M:M,master!L:L) -> JRN_EXPRESS_B2B | Y56: JRN EXPRESS | Z56: 46711 | AA56: 413293 | AB56: =COUNTIFS(Base!$C:$C,MAPPING!X56) -> 1
C57: COOKD_VENTURES_B2B | D57: COOKD VENTURES PRIVATE LIMITED | F57: COOKD_VENTURES_B2B | G57: COOKD VENTURES PRIVATE LIMITED | K57: Modenik_TRP_B2B | L57: MODENIK LIFESTYLE PRIVATE LIMITED | M57: - | N57: Balu | X57: =_xlfn.XLOOKUP(Y57,master!M:M,master!L:L) -> AGILITAS_B2B | Y57: AGILITAS BRANDS PRIVATE LIMITED | Z57: 5357 | AA57: 250422 | AB57: =COUNTIFS(Base!$C:$C,MAPPING!X57) -> 1
... C81: APEX_APPARELS_B2B | D81: APEX APPARELS | F81: APEX_APPARELS_B2B | G81: APEX APPARELS | K81: ASIAN_FOOTWEARS_B2B | L81: ASIAN FOOTWEARS PRIVATE LIMITED | M81: - | N81: Rahul | X81: =_xlfn.XLOOKUP(Y81,master!M:M,master!L:L) -> AJANTA_SHOES_B2B | Y81: AJANTA SHOES (INDIA) PRIVATE LIMITED | Z81: 47545 | AA81: 594150 | AB81: =COUNTIFS(Base!$C:$C,MAPPING!X81) -> 1
C82: Bombay_Wheels_B2B | D82: BOMBAY WHEELS | F82: Bombay_Wheels_B2B | G82: BOMBAY WHEELS | K82: AdityaBirlaFashion_b2b | L82: ADITYA BIRLA FASHION AND RETAIL LIMITED | M82: - | N82: Vandana | X82: =_xlfn.XLOOKUP(Y82,[1]rpk!$B:$B,[1]rpk!$A:$A) -> SME_EXPRESS_B2B | Y82: SME EXPRESS | Z82: 64967 | AA82: 737724 | AB82: =COUNTIFS(Base!$C:$C,MAPPING!X82) -> 1
C83: Libas_B2B_FTL | D83: ZIVORE APPAREL PRIVATE LIMITED | F83: Libas_B2B_FTL | G83: ZIVORE APPAREL PRIVATE LIMITED | K83: THE_EARTH_B2B | L83: THE EARTH STORE | M83: New client (May'26) | N83: Pramod | X83: =_xlfn.XLOOKUP(Y83,[1]rpk!$B:$B,[1]rpk!$A:$A) -> FMI_LTD_B2B | Y83: FMI LIMITED | Z83: 118964 | AA83: 935853 | AB83: =COUNTIFS(Base!$C:$C,MAPPING!X83) -> 1
C84: PINPOINT_SALES_LLP | D84: PIN POINT SALES LLP | F84: PINPOINT_SALES_LLP | G84: PIN POINT SALES LLP | K84: ALPINO_B2B | L84: ALPINO HEALTH FOODS PRIVATE LIMITED | M84: New client (Feb'26) | N84: Pooja | X84: =_xlfn.XLOOKUP(Y84,master!M:M,master!L:L) -> Griffen_Logistics_B2B | Y84: GRIFFEN LOGISTICS | Z84: 16283 | AA84: 294758 | AB84: =COUNTIFS(Base!$C:$C,MAPPING!X84) -> 1
C85: DISMANTLE_DIGITAL_B2B | D85: DISMANTLE DIGITAL PRIVATE LIMITED | F85: DISMANTLE_DIGITAL_B2B | G85: DISMANTLE DIGITAL PRIVATE LIMITED | K85: TBJ_IMPEX_B2B | L85: TBJ IMPEX PRIVATE LIMITED | M85: New client (May'26) | N85: Sudhanshu | X85: =_xlfn.XLOOKUP(Y85,master!M:M,master!L:L) -> 4TH_PHARMA_B2B | Y85: 4THD PHARMA PRIVATE LIMITED | Z85: 1230 | AA85: 76296 | AB85: =COUNTIFS(Base!$C:$C,MAPPING!X85) -> 1
C86: J3J_ECOM_B2B | D86: J3J ECOM PRIVATE LIMITED | F86: J3J_ECOM_B2B | G86: J3J ECOM PRIVATE LIMITED | K86: KMCR_SOLUTION_B2B | L86: KMCR SOLUTIONS (OPC) PRIVATE LIMITED | M86: - | N86: Pallavi | X86: =_xlfn.XLOOKUP(Y86,master!M:M,master!L:L) -> KIYAN_ENTERPRISES_B2B | Y86: KIYAN ENTERPRISES | Z86: 33628 | AA86: 369649 | AB86: =COUNTIFS(Base!$C:$C,MAPPING!X86) -> 1
C87: Shipclues_B2B | D87: Shipclues Technologies Private Limited | F87: Shipclues_B2B | G87: Shipclues Technologies Private Limited | K87: Pantaloons_B2B | L87: ADITYA BIRLA FASHION AND RETAIL LIMITED | M87: New client (jun'25) | N87: Gaurav Narayan | X87: =_xlfn.XLOOKUP(Y87,[1]rpk!$B:$B,[1]rpk!$A:$A) -> SAYAJI_B2B | Y87: SAYAJI FOODS PRIVATE LIMITED | Z87: 1396 | AA87: 26868 | AB87: =COUNTIFS(Base!$C:$C,MAPPING!X87) -> 1
C88: MERIL_DIAGNOSTICS_B2B | D88: MERIL DIAGNOSTICS PRIVATE LIMITED | F88: MERIL_DIAGNOSTICS_B2B | G88: MERIL DIAGNOSTICS PRIVATE LIMITED | K88: PROZO_INTEGRATED_B2B | L88: PROZO INTEGRATED LOGISTICS PRIVATE LIMITED | M88: New client (Apr'26) | N88: Avinash | X88: =_xlfn.XLOOKUP(Y88,master!M:M,master!L:L) -> SUDHIR_AUTOMOTIVE_B2B | Y88: SUDHIR AUTOMOTIVE INDUSTRIES PRIVATE LIMITED | Z88: 39665 | AA88: 358090 | AB88: =COUNTIFS(Base!$C:$C,MAPPING!X88) -> 1
C89: MICRO_LIFE_B2B | D89: MICRO LIFE SCIENCES PRIVATE LIMITED | F89: MICRO_LIFE_B2B | G89: MICRO LIFE SCIENCES PRIVATE LIMITED | K89: STYLE_WAVES_B2B | L89: STYLE WAVES LLP | M89: New client (Oct'25) | N89: Avinash | X89: =_xlfn.XLOOKUP(Y89,master!M:M,master!L:L) -> MEDITREE_AMD_B2B | Y89: MEDITREE LIFECARE LLP | Z89: 4511 | AA89: 42942 | AB89: =COUNTIFS(Base!$C:$C,MAPPING!X89) -> 1
C90: Jayshree_Textile_B2B | D90: Grasim Industries Limited | F90: Jayshree_Textile_B2B | G90: Grasim Industries Limited | K90: 1MG_B2B | L90: TATA 1MG HEALTHCARE SOLUTIONS PRIVATE LIMITED | M90: New client (Mar'26) | N90: Avinash | X90: =_xlfn.XLOOKUP(Y90,master!M:M,master!L:L) -> SNITCH_B2B | Y90: SNITCH APPARELS PRIVATE LIMITED | Z90: 16471 | AA90: 247989 | AB90: =COUNTIFS(Base!$C:$C,MAPPING!X90) -> 1
C91: FURRPLE_B2B | D91: FURRPLE | F91: FURRPLE_B2B | G91: FURRPLE | K91: ADITYA_ENTERPRISES_B2B | L91: ADITYA ENTERPRISES | M91: New client (Mar'26) | N91: Sanchit | X91: =_xlfn.XLOOKUP(Y91,master!M:M,master!L:L) -> ACEFOUR_ACCESSORIES_B2B | Y91: ACEFOUR ACCESSORIES PRIVATE LIMITED | Z91: 29499 | AA91: 238874 | AB91: =COUNTIFS(Base!$C:$C,MAPPING!X91) -> 1
C92: Sassafras_B2B | D92: Kalyr Retail Private Limited | F92: Sassafras_B2B | G92: Kalyr Retail Private Limited | K92: ADL_International_B2B | L92: ADL INTERNATIONAL | M92: New(July) | N92: Pallavi | X92: =_xlfn.XLOOKUP(Y92,master!M:M,master!L:L) -> XYXX_APPARELS_B2B | Y92: XYXX APPARELS PRIVATE LIMITED | Z92: 24048 | AA92: 394099 | AB92: =COUNTIFS(Base!$C:$C,MAPPING!X92) -> 1
...
